Workbook

Sheet Model
A1: Difficulty-score model — weights on normalized P1..P8
A3: param | B3: weight | C3: norm_min | D3: norm_max | E3: note
A4: FLOOR | B4: 0.0765 | E4: score floor (tutorial baseline)
A5: P1_words | B5: 3.2901 | C5: 1 | D5: 5 | E5: number of words (coarse length lever)
A6: P2_wordlen | B6: 0.9 | C6: 4 | D6: 8 | E6: max word length
A7: P3_zipf | B7: 0.1 | C7: 1 | D7: 6 | E7: rarity band (1 common .. 6 rare)
A8: P4_scramble | B8: 2.3472 | C8: 0 | D8: 1 | E8: scramble score (already 0..1)
A9: P5_traps | B9: 0.3521 | C9: 0 | D9: 2 | E9: trap anagrams
A10: P6_answerlen | B10: 0.3329 | C10: 3 | D10: 14 | E10: answer letters
A11: P7_pun | B11: 0.6035 | C11: 0 | D11: 1 | E11: pun type encoded
A12: P8_opacity | B12: 0.1 | C12: 1 | D12: 5 | E12: cartoon transparency, used inverted (5-P8)/4
A15: pun_type encoding
A17: direct | B17: 0
A18: idiom | B18: 0.33
A19: homophone | B19: 0.66
A20: Score formula (per Table row): FLOOR + Σ weight_i · normalized(P_i) | B20: 1

Sheet Table
A1: level | B1: words_count | C1: word_len_min | D1: word_len_max | E1: zipf_band | F1: scramble_score | G1: trap_anagrams | H1: answer_letters | I1: answer_words | J1: pun_type | K1: cartoon_transparency | L1: free_hint_worth | M1: target_solve_time_sec | N1: target_hint_usage_pct | O1: difficulty_score | P1: curve_role | Q1: notes
A2: 1 | B2: 1 | C2: 4 | D2: 4 | E2: 1 | F2: 0.33 | G2: 0 | H2: 3 | I2: 1 | J2: direct | K2: 5 | L2: 4 | M2: 25 | N2: 3 | O2: =Model!$B$4+Model!$B$5*((B2-1)/4)+Model!$B$6*((D2-4)/4)+Model!$B$7*((E2-1)/5)+Model!$B$8*(F2)+Model!$B$9*((G2)/2)+Model!$B$10*((H2-3)/11)+Model!$B$11*(IF(J2="double-layer",1,IF(J2="homophone",0.66,IF(J2="idiom",0.33,0))))+Model!$B$12*((5-K2)/4) | P2: milestone | Q2: Tutorial floor: 1 word, top lexicon, no traps, direct pun
A3: 2 | B3: 1 | C3: 4 | D3: 4 | E3: 1 | F3: 0.3 | G3: 0 | H3: 3 | I3: 1 | J3: direct | K3: 5 | L3: 4 | M3: 23 | N3: 3 | O3: =Model!$B$4+Model!$B$5*((B3-1)/4)+Model!$B$6*((D3-4)/4)+Model!$B$7*((E3-1)/5)+Model!$B$8*(F3)+Model!$B$9*((G3)/2)+Model!$B$10*((H3-3)/11)+Model!$B$11*(IF(J3="double-layer",1,IF(J3="homophone",0.66,IF(J3="idiom",0.33,0))))+Model!$B$12*((5-K3)/4) | P3: ramp
A4: 3 | B4: 1 | C4: 4 | D4: 4 | E4: 1 | F4: 0.33 | G4: 0 | H4: 3 | I4: 1 | J4: direct | K4: 5 | L4: 4 | M4: 25 | N4: 3 | O4: =Model!$B$4+Model!$B$5*((B4-1)/4)+Model!$B$6*((D4-4)/4)+Model!$B$7*((E4-1)/5)+Model!$B$8*(F4)+Model!$B$9*((G4)/2)+Model!$B$10*((H4-3)/11)+Model!$B$11*(IF(J4="double-layer",1,IF(J4="homophone",0.66,IF(J4="idiom",0.33,0))))+Model!$B$12*((5-K4)/4) | P4: ramp
A5: 4 | B5: 1 | C5: 4 | D5: 4 | E5: 1 | F5: 0.36 | G5: 0 | H5: 3 | I5: 1 | J5: direct | K5: 5 | L5: 4 | M5: 27 | N5: 3 | O5: =Model!$B$4+Model!$B$5*((B5-1)/4)+Model!$B$6*((D5-4)/4)+Model!$B$7*((E5-1)/5)+Model!$B$8*(F5)+Model!$B$9*((G5)/2)+Model!$B$10*((H5-3)/11)+Model!$B$11*(IF(J5="double-layer",1,IF(J5="homophone",0.66,IF(J5="idiom",0.33,0))))+Model!$B$12*((5-K5)/4) | P5: ramp
A6: 5 | B6: 1 | C6: 4 | D6: 4 | E6: 2 | F6: 0.36 | G6: 0 | H6: 3 | I6: 1 | J6: direct | K6: 5 | L6: 5 | M6: 28 | N6: 3 | O6: =Model!$B$4+Model!$B$5*((B6-1)/4)+Model!$B$6*((D6-4)/4)+Model!$B$7*((E6-1)/5)+Model!$B$8*(F6)+Model!$B$9*((G6)/2)+Model!$B$10*((H6-3)/11)+Model!$B$11*(IF(J6="double-layer",1,IF(J6="homophone",0.66,IF(J6="idiom",0.33,0))))+Model!$B$12*((5-K6)/4) | P6: ramp
A7: 6 | B7: 1 | C7: 4 | D7: 4 | E7: 2 | F7: 0.3 | G7: 0 | H7: 3 | I7: 1 | J7: direct | K7: 5 | L7: 5 | M7: 24 | N7: 3 | O7: =Model!$B$4+Model!$B$5*((B7-1)/4)+Model!$B$6*((D7-4)/4)+Model!$B$7*((E7-1)/5)+Model!$B$8*(F7)+Model!$B$9*((G7)/2)+Model!$B$10*((H7-3)/11)+Model!$B$11*(IF(J7="double-layer",1,IF(J7="homophone",0.66,IF(J7="idiom",0.33,0))))+Model!$B$12*((5-K7)/4) | P7: ramp
A8: 7 | B8: 2 | C8: 4 | D8: 4 | E8: 2 | F8: 0.33 | G8: 0 | H8: 3 | I8: 1 | J8: direct | K8: 5 | L8: 5 | M8: 50 | N8: 11 | O8: =Model!$B$4+Model!$B$5*((B8-1)/4)+Model!$B$6*((D8-4)/4)+Model!$B$7*((E8-1)/5)+Model!$B$8*(F8)+Model!$B$9*((G8)/2)+Model!$B$10*((H8-3)/11)+Model!$B$11*(IF(J8="double-layer",1,IF(J8="homophone",0.66,IF(J8="idiom",0.33,0))))+Model!$B$12*((5-K8)/4) | P8: ramp
A9: 8 | B9: 2 | C9: 4 | D9: 4 | E9: 2 | F9: 0.33 | G9: 0 | H9: 3 | I9: 1 | J9: direct | K9: 5 | L9: 5 | M9: 50 | N9: 11 | O9: =Model!$B$4+Model!$B$5*((B9-1)/4)+Model!$B$6*((D9-4)/4)+Model!$B$7*((E9-1)/5)+Model!$B$8*(F9)+Model!$B$9*((G9)/2)+Model!$B$10*((H9-3)/11)+Model!$B$11*(IF(J9="double-layer",1,IF(J9="homophone",0.66,IF(J9="idiom",0.33,0))))+Model!$B$12*((5-K9)/4) | P9: ramp
A10: 9 | B10: 2 | C10: 4 | D10: 4 | E10: 2 | F10: 0.33 | G10: 0 | H10: 4 | I10: 1 | J10: direct | K10: 4 | L10: 5 | M10: 51 | N10: 11 | O10: =Model!$B$4+Model!$B$5*((B10-1)/4)+Model!$B$6*((D10-4)/4)+Model!$B$7*((E10-1)/5)+Model!$B$8*(F10)+Model!$B$9*((G10)/2)+Model!$B$10*((H10-3)/11)+Model!$B$11*(IF(J10="double-layer",1,IF(J10="homophone",0.66,IF(J10="idiom",0.33,0))))+Model!$B$12*((5-K10)/4) | P10: ramp
A11: 10 | B11: 2 | C11: 4 | D11: 4 | E11: 2 | F11: 0.4 | G11: 0 | H11: 4 | I11: 1 | J11: direct | K11: 4 | L11: 5 | M11: 56 | N11: 13 | O11: =Model!$B$4+Model!$B$5*((B11-1)/4)+Model!$B$6*((D11-4)/4)+Model!$B$7*((E11-1)/5)+Model!$B$8*(F11)+Model!$B$9*((G11)/2)+Model!$B$10*((H11-3)/11)+Model!$B$11*(IF(J11="double-layer",1,IF(J11="homophone",0.66,IF(J11="idiom",0.33,0))))+Model!$B$12*((5-K11)/4) | P11: spike | Q11: SPIKE: first full 3-word warmup pressure; scramble sawtooth peaks
A12: 11 | B12: 2 | C12: 4 | D12: 4 | E12: 2 | F12: 0.27 | G12: 0 | H12: 4 | I12: 1 | J12: direct | K12: 4 | L12: 5 | M12: 47 | N12: 10 | O12: =Model!$B$4+Model!$B$5*((B12-1)/4)+Model!$B$6*((D12-4)/4)+Model!$B$7*((E12-1)/5)+Model!$B$8*(F12)+Model!$B$9*((G12)/2)+Model!$B$10*((H12-3)/11)+Model!$B$11*(IF(J12="double-layer",1,IF(J12="homophone",0.66,IF(J12="idiom",0.33,0))))+Model!$B$12*((5-K12)/4) | P12: relief | Q12: Relief: easier scramble after the spike (breather)
A13: 12 | B13: 2 | C13: 4 | D13: 4 | E13: 2 | F13: 0.33 | G13: 0 | H13: 4 | I13: 1 | J13: direct | K13: 4 | L13: 5 | M13: 51 | N13: 11 | O13: =Model!$B$4+Model!$B$5*((B13-1)/4)+Model!$B$6*((D13-4)/4)+Model!$B$7*((E13-1)/5)+Model!$B$8*(F13)+Model!$B$9*((G13)/2)+Model!$B$10*((H13-3)/11)+Model!$B$11*(IF(J13="double-layer",1,IF(J13="homophone",0.66,IF(J13="idiom",0.33,0))))+Model!$B$12*((5-K13)/4) | P13: ramp | Q13: ANCHOR (=prototype v12); pinned P1-P8
A14: 13 | B14: 2 | C14: 4 | D14: 4 | E14: 2 | F14: 0.34 | G14: 0 | H14: 4 | I14: 1 | J14: direct | K14: 4 | L14: 5 | M14: 52 | N14: 12 | O14: =Model!$B$4+Model!$B$5*((B14-1)/4)+Model!$B$6*((D14-4)/4)+Model!$B$7*((E14-1)/5)+Model!$B$8*(F14)+Model!$B$9*((G14)/2)+Model!$B$10*((H14-3)/11)+Model!$B$11*(IF(J14="double-layer",1,IF(J14="homophone",0.66,IF(J14="idiom",0.33,0))))+Model!$B$12*((5-K14)/4) | P14: ramp
A15: 14 | B15: 2 | C15: 4 | D15: 4 | E15: 2 | F15: 0.38 | G15: 0 | H15: 4 | I15: 1 | J15: direct | K15: 4 | L15: 5 | M15: 55 | N15: 13 | O15: =Model!$B$4+Model!$B$5*((B15-1)/4)+Model!$B$6*((D15-4)/4)+Model!$B$7*((E15-1)/5)+Model!$B$8*(F15)+Model!$B$9*((G15)/2)+Model!$B$10*((H15-3)/11)+Model!$B$11*(IF(J15="double-layer",1,IF(J15="homophone",0.66,IF(J15="idiom",0.33,0))))+Model!$B$12*((5-K15)/4) | P15: ramp
A16: 15 | B16: 2 | C16: 4 | D16: 4 | E16: 2 | F16: 0.39 | G16: 0 | H16: 4 | I16: 1 | J16: direct | K16: 4 | L16: 5 | M16: 55 | N16: 13 | O16: =Model!$B$4+Model!$B$5*((B16-1)/4)+Model!$B$6*((D16-4)/4)+Model!$B$7*((E16-1)/5)+Model!$B$8*(F16)+Model!$B$9*((G16)/2)+Model!$B$10*((H16-3)/11)+Model!$B$11*(IF(J16="double-layer",1,IF(J16="homophone",0.66,IF(J16="idiom",0.33,0))))+Model!$B$12*((5-K16)/4) | P16: ramp
A17: 16 | B17: 2 | C17: 4 | D17: 4 | E17: 3 | F17: 0.34 | G17: 0 | H17: 4 | I17: 1 | J17: direct | K17: 4 | L17: 5 | M17: 53 | N17: 12 | O17: =Model!$B$4+Model!$B$5*((B17-1)/4)+Model!$B$6*((D17-4)/4)+Model!$B$7*((E17-1)/5)+Model!$B$8*(F17)+Model!$B$9*((G17)/2)+Model!$B$10*((H17-3)/11)+Model!$B$11*(IF(J17="double-layer",1,IF(J17="homophone",0.66,IF(J17="idiom",0.33,0))))+Model!$B$12*((5-K17)/4) | P17: ramp
A18: 17 | B18: 2 | C18: 4 | D18: 4 | E18: 3 | F18: 0.38 | G18: 0 | H18: 4 | I18: 1 | J18: direct | K18: 4 | L18: 5 | M18: 55 | N18: 13 | O18: =Model!$B$4+Model!$B$5*((B18-1)/4)+Model!$B$6*((D18-4)/4)+Model!$B$7*((E18-1)/5)+Model!$B$8*(F18)+Model!$B$9*((G18)/2)+Model!$B$10*((H18-3)/11)+Model!$B$11*(IF(J18="double-layer",1,IF(J18="homophone",0.66,IF(J18="idiom",0.33,0))))+Model!$B$12*((5-K18)/4) | P18: ramp
A19: 18 | B19: 2 | C19: 4 | D19: 4 | E19: 3 | F19: 0.4 | G19: 0 | H19: 4 | I19: 1 | J19: direct | K19: 4 | L19: 6 | M19: 57 | N19: 14 | O19: =Model!$B$4+Model!$B$5*((B19-1)/4)+Model!$B$6*((D19-4)/4)+Model!$B$7*((E19-1)/5)+Model!$B$8*(F19)+Model!$B$9*((G19)/2)+Model!$B$10*((H19-3)/11)+Model!$B$11*(IF(J19="double-layer",1,IF(J19="homophone",0.66,IF(J19="idiom",0.33,0))))+Model!$B$12*((5-K19)/4) | P19: ramp
A20: 19 | B20: 2 | C20: 4 | D20: 4 | E20: 3 | F20: 0.41 | G20: 0 | H20: 4 | I20: 1 | J20: direct | K20: 4 | L20: 6 | M20: 57 | N20: 14 | O20: =Model!$B$4+Model!$B$5*((B20-1)/4)+Model!$B$6*((D20-4)/4)+Model!$B$7*((E20-1)/5)+Model!$B$8*(F20)+Model!$B$9*((G20)/2)+Model!$B$10*((H20-3)/11)+Model!$B$11*(IF(J20="double-layer",1,IF(J20="homophone",0.66,IF(J20="idiom",0.33,0))))+Model!$B$12*((5-K20)/4) | P20: ramp
A21: 20 | B21: 2 | C21: 4 | D21: 4 | E21: 3 | F21: 0.49 | G21: 0 | H21: 4 | I21: 1 | J21: homophone | K21: 4 | L21: 6 | M21: 75 | N21: 21 | O21: =Model!$B$4+Model!$B$5*((B21-1)/4)+Model!$B$6*((D21-4)/4)+Model!$B$7*((E21-1)/5)+Model!$B$8*(F21)+Model!$B$9*((G21)/2)+Model!$B$10*((H21-3)/11)+Model!$B$11*(IF(J21="double-layer",1,IF(J21="homophone",0.66,IF(J21="idiom",0.33,0))))+Model!$B$12*((5-K21)/4) | P21: spike | Q21: SPIKE: first homophone pun locks in as the block standard
A22: 21 | B22: 2 | C22: 4 | D22: 4 | E22: 3 | F22: 0.37 | G22: 0 | H22: 4 | I22: 1 | J22: homophone | K22: 4 | L22: 6 | M22: 66 | N22: 18 | O22: =Model!$B$4+Model!$B$5*((B22-1)/4)+Model!$B$6*((D22-4)/4)+Model!$B$7*((E22-1)/5)+Model!$B$8*(F22)+Model!$B$9*((G22)/2)+Model!$B$10*((H22-3)/11)+Model!$B$11*(IF(J22="double-layer",1,IF(J22="homophone",0.66,IF(J22="idiom",0.33,0))))+Model!$B$12*((5-K22)/4) | P22: relief | Q22: Relief: easier scramble after the spike (breather)
A23: 22 | B23: 2 | C23: 4 | D23: 4 | E23: 3 | F23: 0.41 | G23: 0 | H23: 4 | I23: 1 | J23: homophone | K23: 4 | L23: 6 | M23: 69 | N23: 19 | O23: =Model!$B$4+Model!$B$5*((B23-1)/4)+Model!$B$6*((D23-4)/4)+Model!$B$7*((E23-1)/5)+Model!$B$8*(F23)+Model!$B$9*((G23)/2)+Model!$B$10*((H23-3)/11)+Model!$B$11*(IF(J23="double-layer",1,IF(J23="homophone",0.66,IF(J23="idiom",0.33,0))))+Model!$B$12*((5-K23)/4) | P23: ramp
A24: 23 | B24: 2 | C24: 4 | D24: 4 | E24: 3 | F24: 0.45 | G24: 0 | H24: 4 | I24: 1 | J24: homophone | K24: 4 | L24: 6 | M24: 72 | N24: 20 | O24: =Model!$B$4+Model!$B$5*((B24-1)/4)+Model!$B$6*((D24-4)/4)+Model!$B$7*((E24-1)/5)+Model!$B$8*(F24)+Model!$B$9*((G24)/2)+Model!$B$10*((H24-3)/11)+Model!$B$11*(IF(J24="double-layer",1,IF(J24="homophone",0.66,IF(J24="idiom",0.33,0))))+Model!$B$12*((5-K24)/4) | P24: ramp | Q24: ANCHOR (=prototype v23); pinned P1-P8
A25: 24 | B25: 2 | C25: 4 | D25: 4 | E25: 3 | F25: 0.49 | G25: 0 | H25: 4 | I25: 1 | J25: homophone | K25: 4 | L25: 6 | M25: 75 | N25: 21 | O25: =Model!$B$4+Model!$B$5*((B25-1)/4)+Model!$B$6*((D25-4)/4)+Model!$B$7*((E25-1)/5)+Model!$B$8*(F25)+Model!$B$9*((G25)/2)+Model!$B$10*((H25-3)/11)+Model!$B$11*(IF(J25="double-layer",1,IF(J25="homophone",0.66,IF(J25="idiom",0.33,0))))+Model!$B$12*((5-K25)/4) | P25: ramp
A26: 25 | B26: 2 | C26: 4 | D26: 4 | E26: 3 | F26: 0.51 | G26: 0 | H26: 5 | I26: 1 | J26: homophone | K26: 4 | L26: 6 | M26: 77 | N26: 22 | O26: =Model!$B$4+Model!$B$5*((B26-1)/4)+Model!$B$6*((D26-4)/4)+Model!$B$7*((E26-1)/5)+Model!$B$8*(F26)+Model!$B$9*((G26)/2)+Model!$B$10*((H26-3)/11)+Model!$B$11*(IF(J26="double-layer",1,IF(J26="homophone",0.66,IF(J26="idiom",0.33,0))))+Model!$B$12*((5-K26)/4) | P26: ramp
A27: 26 | B27: 2 | C27: 4 | D27: 4 | E27: 3 | F27: 0.46 | G27: 0 | H27: 5 | I27: 1 | J27: homophone | K27: 4 | L27: 6 | M27: 73 | N27: 20 | O27: =Model!$B$4+Model!$B$5*((B27-1)/4)+Model!$B$6*((D27-4)/4)+Model!$B$7*((E27-1)/5)+Model!$B$8*(F27)+Model!$B$9*((G27)/2)+Model!$B$10*((H27-3)/11)+Model!$B$11*(IF(J27="double-layer",1,IF(J27="homophone",0.66,IF(J27="idiom",0.33,0))))+Model!$B$12*((5-K27)/4) | P27: ramp
A28: 27 | B28: 2 | C28: 4 | D28: 4 | E28: 4 | F28: 0.5 | G28: 0 | H28: 6 | I28: 1 | J28: homophone | K28: 4 | L28: 6 | M28: 78 | N28: 22 | O28: =Model!$B$4+Model!$B$5*((B28-1)/4)+Model!$B$6*((D28-4)/4)+Model!$B$7*((E28-1)/5)+Model!$B$8*(F28)+Model!$B$9*((G28)/2)+Model!$B$10*((H28-3)/11)+Model!$B$11*(IF(J28="double-layer",1,IF(J28="homophone",0.66,IF(J28="idiom",0.33,0))))+Model!$B$12*((5-K28)/4) | P28: ramp
A29: 28 | B29: 2 | C29: 4 | D29: 4 | E29: 4 | F29: 0.52 | G29: 0 | H29: 6 | I29: 1 | J29: homophone | K29: 4 | L29: 6 | M29: 79 | N29: 23 | O29: =Model!$B$4+Model!$B$5*((B29-1)/4)+Model!$B$6*((D29-4)/4)+Model!$B$7*((E29-1)/5)+Model!$B$8*(F29)+Model!$B$9*((G29)/2)+Model!$B$10*((H29-3)/11)+Model!$B$11*(IF(J29="double-layer",1,IF(J29="homophone",0.66,IF(J29="idiom",0.33,0))))+Model!$B$12*((5-K29)/4) | P29: ramp
A30: 29 | B30: 2 | C30: 4 | D30: 4 | E30: 4 | F30: 0.53 | G30: 0 | H30: 7 | I30: 2 | J30: homophone | K30: 4 | L30: 6 | M30: 81 | N30: 23 | O30: =Model!$B$4+Model!$B$5*((B30-1)/4)+Model!$B$6*((D30-4)/4)+Model!$B$7*((E30-1)/5)+Model!$B$8*(F30)+Model!$B$9*((G30)/2)+Model!$B$10*((H30-3)/11)+Model!$B$11*(IF(J30="double-layer",1,IF(J30="homophone",0.66,IF(J30="idiom",0.33,0))))+Model!$B$12*((5-K30)/4) | P30: ramp
A31: 30 | B31: 2 | C31: 4 | D31: 4 | E31: 4 | F31: 0.62 | G31: 0 | H31: 7 | I31: 2 | J31: homophone | K31: 4 | L31: 6 | M31: 87 | N31: 26 | O31: =Model!$B$4+Model!$B$5*((B31-1)/4)+Model!$B$6*((D31-4)/4)+Model!$B$7*((E31-1)/5)+Model!$B$8*(F31)+Model!$B$9*((G31)/2)+Model!$B$10*((H31-3)/11)+Model!$B$11*(IF(J31="double-layer",1,IF(J31="homophone",0.66,IF(J31="idiom",0.33,0))))+Model!$B$12*((5-K31)/4) | P31: spike | Q31: SPIKE: approach to first 2-word answer; traps loom
A32: 31 | B32: 2 | C32: 4 | D32: 5 | E32: 4 | F32: 0.5 | G32: 1 | H32: 7 | I32: 2 | J32: homophone | K32: 3 | L32: 6 | M32: 91 | N32: 28 | O32: =Model!$B$4+Model!$B$5*((B32-1)/4)+Model!$B$6*((D32-4)/4)+Model!$B$7*((E32-1)/5)+Model!$B$8*(F32)+Model!$B$9*((G32)/2)+Model!$B$10*((H32-3)/11)+Model!$B$11*(IF(J32="double-layer",1,IF(J32="homophone",0.66,IF(J32="idiom",0.33,0))))+Model!$B$12*((5-K32)/4) | P32: relief | Q32: Relief: easier scramble after the spike (breather)
A33: 32 | B33: 2 | C33: 4 | D33: 5 | E33: 4 | F33: 0.54 | G33: 1 | H33: 8 | I33: 2 | J33: homophone | K33: 3 | L33: 6 | M33: 95 | N33: 29 | O33: =Model!$B$4+Model!$B$5*((B33-1)/4)+Model!$B$6*((D33-4)/4)+Model!$B$7*((E33-1)/5)+Model!$B$8*(F33)+Model!$B$9*((G33)/2)+Model!$B$10*((H33-3)/11)+Model!$B$11*(IF(J33="double-layer",1,IF(J33="homophone",0.66,IF(J33="idiom",0.33,0))))+Model!$B$12*((5-K33)/4) | P33: ramp
A34: 33 | B34: 2 | C34: 4 | D34: 5 | E34: 4 | F34: 0.59 | G34: 1 | H34: 8 | I34: 2 | J34: homophone | K34: 3 | L34: 6 | M34: 98 | N34: 31 | O34: =Model!$B$4+Model!$B$5*((B34-1)/4)+Model!$B$6*((D34-4)/4)+Model!$B$7*((E34-1)/5)+Model!$B$8*(F34)+Model!$B$9*((G34)/2)+Model!$B$10*((H34-3)/11)+Model!$B$11*(IF(J34="double-layer",1,IF(J34="homophone",0.66,IF(J34="idiom",0.33,0))))+Model!$B$12*((5-K34)/4) | P34: ramp
A35: 34 | B35: 2 | C35: 4 | D35: 5 | E35: 4 | F35: 0.6 | G35: 1 | H35: 9 | I35: 2 | J35: homophone | K35: 3 | L35: 7 | M35: 100 | N35: 31 | O35: =Model!$B$4+Model!$B$5*((B35-1)/4)+Model!$B$6*((D35-4)/4)+Model!$B$7*((E35-1)/5)+Model!$B$8*(F35)+Model!$B$9*((G35)/2)+Model!$B$10*((H35-3)/11)+Model!$B$11*(IF(J35="double-layer",1,IF(J35="homophone",0.66,IF(J35="idiom",0.33,0))))+Model!$B$12*((5-K35)/4) | P35: spike | Q35: ANCHOR (=prototype v34); pinned P1-P8
A36: 35 | B36: 2 | C36: 4 | D36: 5 | E36: 4 | F36: 0.61 | G36: 1 | H36: 9 | I36: 2 | J36: homophone | K36: 3 | L36: 7 | M36: 100 | N36: 31 | O36: =Model!$B$4+Model!$B$5*((B36-1)/4)+Model!$B$6*((D36-4)/4)+Model!$B$7*((E36-1)/5)+Model!$B$8*(F36)+Model!$B$9*((G36)/2)+Model!$B$10*((H36-3)/11)+Model!$B$11*(IF(J36="double-layer",1,IF(J36="homophone",0.66,IF(J36="idiom",0.33,0))))+Model!$B$12*((5-K36)/4) | P36: ramp
A37: 36 | B37: 2 | C37: 4 | D37: 5 | E37: 4 | F37: 0.52 | G37: 1 | H37: 8 | I37: 2 | J37: homophone | K37: 3 | L37: 7 | M37: 93 | N37: 29 | O37: =Model!$B$4+Model!$B$5*((B37-1)/4)+Model!$B$6*((D37-4)/4)+Model!$B$7*((E37-1)/5)+Model!$B$8*(F37)+Model!$B$9*((G37)/2)+Model!$B$10*((H37-3)/11)+Model!$B$11*(IF(J37="double-layer",1,IF(J37="homophone",0.66,IF(J37="idiom",0.33,0))))+Model!$B$12*((5-K37)/4) | P37: ramp
A38: 37 | B38: 2 | C38: 4 | D38: 5 | E38: 4 | F38: 0.53 | G38: 1 | H38: 8 | I38: 2 | J38: homophone | K38: 3 | L38: 7 | M38: 94 | N38: 29 | O38: =Model!$B$4+Model!$B$5*((B38-1)/4)+Model!$B$6*((D38-4)/4)+Model!$B$7*((E38-1)/5)+Model!$B$8*(F38)+Model!$B$9*((G38)/2)+Model!$B$10*((H38-3)/11)+Model!$B$11*(IF(J38="double-layer",1,IF(J38="homophone",0.66,IF(J38="idiom",0.33,0))))+Model!$B$12*((5-K38)/4) | P38: ramp
A39: 38 | B39: 2 | C39: 4 | D39: 5 | E39: 4 | F39: 0.5 | G39: 1 | H39: 8 | I39: 2 | J39: homophone | K39: 3 | L39: 7 | M39: 92 | N39: 28 | O39: =Model!$B$4+Model!$B$5*((B39-1)/4)+Model!$B$6*((D39-4)/4)+Model!$B$7*((E39-1)/5)+Model!$B$8*(F39)+Model!$B$9*((G39)/2)+Model!$B$10*((H39-3)/11)+Model!$B$11*(IF(J39="double-layer",1,IF(J39="homophone",0.66,IF(J39="idiom",0.33,0))))+Model!$B$12*((5-K39)/4) | P39: ramp
A40: 39 | B40: 2 | C40: 4 | D40: 5 | E40: 4 | F40: 0.48 | G40: 1 | H40: 8 | I40: 2 | J40: homophone | K40: 3 | L40: 7 | M40: 91 | N40: 27 | O40: =Model!$B$4+Model!$B$5*((B40-1)/4)+Model!$B$6*((D40-4)/4)+Model!$B$7*((E40-1)/5)+Model!$B$8*(F40)+Model!$B$9*((G40)/2)+Model!$B$10*((H40-3)/11)+Model!$B$11*(IF(J40="double-layer",1,IF(J40="homophone",0.66,IF(J40="idiom",0.33,0))))+Model!$B$12*((5-K40)/4) | P40: ramp
...

Sheet Curve
B22: Spikes at every 10th level; reliefs at the level right after; sublinear trend underneath.
